<?xml version="1.0"?>
<robot name='3RRR VSA'>

  <!--    LINKS    -->
  <link name='link1'>
    <type>L</type>
    <length>70</length>
    <axis>1 0 0</axis>
    <twist>0</twist>
  </link>

  <link name='link2'>
    <type>L</type>
    <length>70</length>
    <axis>1 0 0</axis>
    <twist>0</twist>
  </link>

  <link name='link3'>
    <type>P</type>
    <length>60</length>
    <axis>1 0 0</axis>
    <twist>3.665</twist>
  </link>

  <link name='link4'>
    <type>L</type>
    <length>70</length>
    <axis>1 0 0</axis>
    <twist>0</twist>
  </link>


  <link name='link5'>
    <type>L</type>
    <length>70</length>
    <axis>1 0 0</axis>
    <twist>0</twist>
  </link>

  <link name='link6'>
    <type>P</type>
    <length>70</length>
    <axis>1 0 0</axis>
    <twist>-0.524</twist>
  </link>

  <link name='link7'>
    <type>L</type>
    <length>70</length>
    <axis>1 0 0</axis>
    <twist>0</twist>
  </link>


  <link name='link8'>
    <type>L</type>
    <length>70</length>
    <axis>1 0 0</axis>
    <twist>0</twist>
  </link>

  <link name='link9'>
    <type>P</type>
    <length>70</length>
    <axis>1 0 0</axis>
    <twist>1.57</twist>
  </link>

  <!--   JOINTS   -->
  <joint name="joint1" type="revolute">
    <parent link="base">
    <child link="link1">
    <limit>-3.14 3.14</limit>
    <axis>0 0 1</axis>
    <position>0 0 0</position>
  </joint>

  <joint name="joint2" type="revolute">
    <parent link="link1">
    <child link="link2">
    <limit>-3.14 3.14</limit>
    <axis>0 0 1</axis>
    <position>0 0 0</position>
  </joint>

  <joint name="joint3" type="revolute">
    <parent link="link2">
    <child link="link3">
    <limit>-3.14 3.14</limit>
    <axis>0 0 1</axis>
    <position>0 0 0</position>
  </joint>

  <joint name="joint4" type="revolute">
    <parent link="base">
    <child link="link4">
    <limit>-3.14 3.14</limit>
    <axis>0 0 1</axis>
    <position>130 0 0</position>
  </joint>

  <joint name="joint5" type="revolute">
    <parent link="link4">
    <child link="link5">
    <limit>-3.14 3.14</limit>
    <axis>0 0 1</axis>
    <position>130 0 0</position>
  </joint>

  <joint name="joint6" type="revolute">
    <parent link="link5">
    <child link="link6">
    <limit>-3.14 3.14</limit>
    <axis>0 0 1</axis>
    <position>130 0 0</position>
  </joint>

  <joint name="joint7" type="revolute">
    <parent link="base">
    <child link="link7">
    <limit>-3.14 3.14</limit>
    <axis>0 0 1</axis>
    <position>20 150 0</position>
  </joint>

  <joint name="joint8" type="revolute">
    <parent link="link7">
    <child link="link8">
    <limit>-3.14 3.14</limit>
    <axis>0 0 1</axis>
    <position>20 150 0</position>
  </joint>

  <joint name="joint9" type="revolute">
    <parent link="link8">
    <child link="link9">
    <limit>-3.14 3.14</limit>
    <axis>0 0 1</axis>
    <position>20 150 0</position>
  </joint>

</robot>
